Workbook
Name RangoHistorico: OFFSET(Historico_Simulaciones!$A$1,0,0,COUNTA(Historico_Simulaciones!$A:$A),8)
Name SegmentaciónDeDatos_Categoria: #N/A
Name SegmentaciónDeDatos_Categoria1: #N/A
Name SegmentaciónDeDatos_Ciudad: #N/A
Name SegmentaciónDeDatos_Ciudad1: #N/A
Name SegmentaciónDeDatos_Ciudad2: #N/A
Name SegmentaciónDeDatos_Plataforma: #N/A
Name SegmentaciónDeDatos_Plataforma1: #N/A

Sheet Estadistica_Descriptiva
A1: Total_Venta
A3: Media | B3: 64798.68
A4: Error típico | B4: 7134.1099
A5: Mediana | B5: 59998
A6: Moda | B6: 0
A7: Desviación estándar | B7: 50445.775
A8: Varianza de la muestra | B8: 2.5447762e+09
A9: Curtosis | B9: 0.6413708
A10: Coeficiente de asimetría | B10: 0.82334592
A11: Rango | B11: 209997
A12: Mínimo | B12: 0
A13: Máximo | B13: 209997
A14: Suma | B14: 3239934
A15: Cuenta | B15: 50

Sheet Resumen de Escenarios
B2: Resumen del escenarios
D3: Valores actuales: | E3: PESIMISTA | F3: BASE | G3: Optimista
E4: Creado por Mateo Guerrino el 1/10/2026 | F4: Creado por Mateo Guerrino el 1/10/2026 | G4: Creado por Mateo Guerrino el 1/10/2026
B5: Celdas cambiantes:
C6: $B$3 | D6: 50000 | E6: 45000 | F6: 50000 | G6: 55000
C7: $B$4 | D7: 100 | E7: 80 | F7: 100 | G7: 120
C8: $B$5 | D8: 30000 | E8: 32000 | F8: 30000 | G8: 28000
C9: $B$6 | D9: 1000000 | E9: 1100000 | F9: 1000000 | G9: 900000
B10: Celdas de resultado:
C11: $B$10 | D11: 1000000 | E11: -60000 | F11: 1000000 | G11: 2340000
B12: Notas: La columna de valores actuales representa los valores de las celdas cambiantes
B13: en el momento en que se creó el Informe resumen de escenario. Las celdas cambiantes de
B14: cada escenario se muestran en gris.

Sheet Simulacion_Financiera
A1: SIMULACIÓN FINANCIERA
A3: Precio promedio | B3: 50000
A4: Unidades vendidas | B4: 100
A5: Costo variable por unidad | B5: 30000
A6: Costos fijos | B6: 1000000
A8: Ingresos | B8: =B3*B4 -> 5000000
A9: Costo variable total | B9: =B5*B4 -> 3000000
A10: Beneficio neto | B10: =B8-B9-B6 -> 1000000

Sheet Dashboard Final
A1: DASHBOARD EJECUTIVO DE VENTAS
P2: Sum of Total_Venta | Q2: Ticket Promedio | T2: Cantidad | U2: Total Venta
P3: 3499926 | Q3: 72915.125 | T3: 2 | U3: 119998
A4: VENTAS TOTALES | F4: TICKET PROMEDIO | K4: BENEFICIO PROYECTADO | T4: 1 | U4: 44999
A5: =P3 -> 3499926 | F5: =Q3 -> 72915.125 | K5: =Simulacion_Financiera!B10 -> 1000000 | T5: 1 | U5: 49999
T6: 2 | U6: 119998
P7: Etiquetas de fila | Q7: Sum of Total_Venta | T7: 1 | U7: 59999
P8: 46235 | Q8: 169997 | T8: 2 | U8: 89998
P9: 46236 | Q9: 319995 | T9: 1 | U9: 14999
P10: 46237 | Q10: 179997 | T10: 1 | U10: 39999
P11: 46238 | Q11: 0 | T11: 2 | U11: 0
P12: 46239 | Q12: 119997 | T12: 2 | U12: 0
P13: 46240 | Q13: 169996 | T13: 3 | U13: 119997
P14: 46241 | Q14: 169997 | T14: 1 | U14: 69999
P15: 46242 | Q15: 119998 | T15: 1 | U15: 44999
P16: 46243 | Q16: 149996 | T16: 1 | U16: 49999
P17: 46244 | Q17: 74997 | T17: 2 | U17: 99998
P18: 46245 | Q18: 269995 | T18: 2 | U18: 79998
P19: 46246 | Q19: 269996 | T19: 2 | U19: 119998
P20: 46247 | Q20: 59999 | T20: 3 | U20: 179997 | X20: Etiquetas de fila | Y20: Sum of Total_Venta
P21: 46248 | Q21: 0 | T21: 2 | U21: 139998 | X21: 1 | Y21: 609986
P22: 46249 | Q22: 39999 | T22: 1 | U22: 49999 | X22: 2 | Y22: 1089976
P23: 46250 | Q23: 139997 | T23: 1 | U23: 59999 | X23: 3 | Y23: 1799964
P24: 46251 | Q24: 179997 | T24: 2 | U24: 89998 | X24: Total general | Y24: 3499926
P25: 46252 | Q25: 224996 | T25: 3 | U25: 209997
P26: 46253 | Q26: 74997 | T26: 1 | U26: 0
P27: 46254 | Q27: 29998 | T27: 1 | U27: 49999
P28: 46255 | Q28: 89997 | T28: 1 | U28: 0
P29: 46256 | Q29: 69999 | T29: 2 | U29: 79998
P30: 46257 | Q30: 119998 | T30: 1 | U30: 14999
P31: 46258 | Q31: 0 | T31: 3 | U31: 89997
P32: 46259 | Q32: 0 | T32: 2 | U32: 99998
P33: 46260 | Q33: 79998 | T33: 2 | U33: 59998
P34: 46261 | Q34: 149997 | T34: 1 | U34: 49999
P35: 46262 | Q35: 59999 | T35: 1 | U35: 0
P36: 46263 | Q36: 89998 | T36: 1 | U36: 44999
... P38: 46265 | Q38: 29999 | T38: 1 | U38: 49999
P39: Total general | Q39: 3499926 | T39: 2 | U39: 79998
T40: 1 | U40: 29999
T41: 1 | U41: 39999
...

Sheet Dataset_Principal
A1: ID_Venta | B1: Fecha | C1: ID_Juego | D1: ID_Cliente | E1: Cantidad | F1: Total_Venta
A2: V-001 | B2: 46235 | C2: J-008 | D2: C-005 | E2: 2 | F2: 119998
A3: V-002 | B3: 46236 | C3: J-009 | D3: C-006 | E3: 1 | F3: 44999
A4: V-003 | B4: 46237 | C4: J-007 | D4: C-001 | E4: 1 | F4: 49999
A5: V-004 | B5: 46238 | C5: J-008 | D5: C-005 | E5: 2 | F5: 119998
A6: V-005 | B6: 46239 | C6: J-008 | D6: C-010 | E6: 1 | F6: 59999
A7: V-006 | B7: 46240 | C7: J-009 | D7: C-001 | E7: 2 | F7: 89998
A8: V-007 | B8: 46241 | C8: J-010 | D8: C-003 | E8: 1 | F8: 14999
A9: V-008 | B9: 46242 | C9: J-006 | D9: C-003 | E9: 1 | F9: 39999
A10: V-009 | B10: 46243 | C10: J-004 | D10: C-001 | E10: 2 | F10: 0
A11: V-010 | B11: 46244 | C11: J-004 | D11: C-002 | E11: 2 | F11: 0
A12: V-011 | B12: 46245 | C12: J-006 | D12: C-007 | E12: 3 | F12: 119997
A13: V-012 | B13: 46246 | C13: J-002 | D13: C-001 | E13: 1 | F13: 69999
... A51: V-050 | B51: 46253 | C51: J-006 | D51: C-005 | E51: 2 | F51: 79998

Sheet Calculos
A1: ID_Venta | B1: ID_Juego | C1: Cantidad | D1: Total_Venta | E1: Clasificacion | G1: Prompt usado:
A2: =Dataset_Principal!A2 -> V-001 | B2: =Dataset_Principal!C2 -> J-008 | C2: =Dataset_Principal!E2 -> 2 | D2: =Dataset_Principal!F2 -> 119998 | E2: =IF(AND(D2>=100000,C2>=2),"Venta Alta",IF(D2>=50000,"Venta Media","Venta Baja")) -> Venta Alta | G2: Contexto: Tengo una tabla de ventas de videojuegos en Excel con las columnas Cantidad y Total_Venta. Objetivo: clasificar cada venta como Alta si el total es mayor o igual a $100.000 y se compraron 2 o más unidades; Media si el total es mayor o igual a $50.000; y Baja en los demás casos. Ejemplo: si Total_Venta = 120.000 y Cantidad = 2, debe devolver Venta Alta. Formato: devolveme una fórmula de Excel usando SI e Y.
A3: =Dataset_Principal!A3 -> V-002 | B3: =Dataset_Principal!C3 -> J-009 | C3: =Dataset_Principal!E3 -> 1 | D3: =Dataset_Principal!F3 -> 44999 | E3: =IF(AND(D3>=100000,C3>=2),"Venta Alta",IF(D3>=50000,"Venta Media","Venta Baja")) -> Venta Baja
A4: =Dataset_Principal!A4 -> V-003 | B4: =Dataset_Principal!C4 -> J-007 | C4: =Dataset_Principal!E4 -> 1 | D4: =Dataset_Principal!F4 -> 49999 | E4: =IF(AND(D4>=100000,C4>=2),"Venta Alta",IF(D4>=50000,"Venta Media","Venta Baja")) -> Venta Baja
A5: =Dataset_Principal!A5 -> V-004 | B5: =Dataset_Principal!C5 -> J-008 | C5: =Dataset_Principal!E5 -> 2 | D5: =Dataset_Principal!F5 -> 119998 | E5: =IF(AND(D5>=100000,C5>=2),"Venta Alta",IF(D5>=50000,"Venta Media","Venta Baja")) -> Venta Alta
A6: =Dataset_Principal!A6 -> V-005 | B6: =Dataset_Principal!C6 -> J-008 | C6: =Dataset_Principal!E6 -> 1 | D6: =Dataset_Principal!F6 -> 59999 | E6: =IF(AND(D6>=100000,C6>=2),"Venta Alta",IF(D6>=50000,"Venta Media","Venta Baja")) -> Venta Media
A7: =Dataset_Principal!A7 -> V-006 | B7: =Dataset_Principal!C7 -> J-009 | C7: =Dataset_Principal!E7 -> 2 | D7: =Dataset_Principal!F7 -> 89998 | E7: =IF(AND(D7>=100000,C7>=2),"Venta Alta",IF(D7>=50000,"Venta Media","Venta Baja")) -> Venta Media
A8: =Dataset_Principal!A8 -> V-007 | B8: =Dataset_Principal!C8 -> J-010 | C8: =Dataset_Principal!E8 -> 1 | D8: =Dataset_Principal!F8 -> 14999 | E8: =IF(AND(D8>=100000,C8>=2),"Venta Alta",IF(D8>=50000,"Venta Media","Venta Baja")) -> Venta Baja
A9: =Dataset_Principal!A9 -> V-008 | B9: =Dataset_Principal!C9 -> J-006 | C9: =Dataset_Principal!E9 -> 1 | D9: =Dataset_Principal!F9 -> 39999 | E9: =IF(AND(D9>=100000,C9>=2),"Venta Alta",IF(D9>=50000,"Venta Media","Venta Baja")) -> Venta Baja
A10: =Dataset_Principal!A10 -> V-009 | B10: =Dataset_Principal!C10 -> J-004 | C10: =Dataset_Principal!E10 -> 2 | D10: =Dataset_Principal!F10 -> 0 | E10: =IF(AND(D10>=100000,C10>=2),"Venta Alta",IF(D10>=50000,"Venta Media","Venta Baja")) -> Venta Baja
A11: =Dataset_Principal!A11 -> V-010 | B11: =Dataset_Principal!C11 -> J-004 | C11: =Dataset_Principal!E11 -> 2 | D11: =Dataset_Principal!F11 -> 0 | E11: =IF(AND(D11>=100000,C11>=2),"Venta Alta",IF(D11>=50000,"Venta Media","Venta Baja")) -> Venta Baja
A12: =Dataset_Principal!A12 -> V-011 | B12: =Dataset_Principal!C12 -> J-006 | C12: =Dataset_Principal!E12 -> 3 | D12: =Dataset_Principal!F12 -> 119997 | E12: =IF(AND(D12>=100000,C12>=2),"Venta Alta",IF(D12>=50000,"Venta Media","Venta Baja")) -> Venta Alta
A13: =Dataset_Principal!A13 -> V-012 | B13: =Dataset_Principal!C13 -> J-002 | C13: =Dataset_Principal!E13 -> 1 | D13: =Dataset_Principal!F13 -> 69999 | E13: =IF(AND(D13>=100000,C13>=2),"Venta Alta",IF(D13>=50000,"Venta Media","Venta Baja")) -> Venta Media
A14: =Dataset_Principal!A14 -> V-013 | B14: =Dataset_Principal!C14 -> J-009 | C14: =Dataset_Principal!E14 -> 1 | D14: =Dataset_Principal!F14 -> 44999 | E14: =IF(AND(D14>=100000,C14>=2),"Venta Alta",IF(D14>=50000,"Venta Media","Venta Baja")) -> Venta Baja
... A51: =Dataset_Principal!A51 -> V-050 | B51: =Dataset_Principal!C51 -> J-006 | C51: =Dataset_Principal!E51 -> 2 | D51: =Dataset_Principal!F51 -> 79998 | E51: =IF(AND(D51>=100000,C51>=2),"Venta Alta",IF(D51>=50000,"Venta Media","Venta Baja")) -> Venta Media

Sheet Prevision
A1: Previsión de ventas diarias
A2: La previsión usa las ventas del Dataset_Principal y proyecta los próximos 3 días.
A4: Periodo | B4: Valor_Historico | C4: Valor_Proyectado | D4: Limite_Inferior | E4: Limite_Superior
A5: 46235 | B5: =SUMIF(Dataset_Principal!$B$2:$B$51,A5,Dataset_Principal!$F$2:$F$51) -> 169997
A6: 46236 | B6: =SUMIF(Dataset_Principal!$B$2:$B$51,A6,Dataset_Principal!$F$2:$F$51) -> 44999
A7: 46237 | B7: =SUMIF(Dataset_Principal!$B$2:$B$51,A7,Dataset_Principal!$F$2:$F$51) -> 94998
A8: 46238 | B8: =SUMIF(Dataset_Principal!$B$2:$B$51,A8,Dataset_Principal!$F$2:$F$51) -> 189997
A9: 46239 | B9: =SUMIF(Dataset_Principal!$B$2:$B$51,A9,Dataset_Principal!$F$2:$F$51) -> 109998
A10: 46240 | B10: =SUMIF(Dataset_Principal!$B$2:$B$51,A10,Dataset_Principal!$F$2:$F$51) -> 169996
A11: 46241 | B11: =SUMIF(Dataset_Principal!$B$2:$B$51,A11,Dataset_Principal!$F$2:$F$51) -> 44998
A12: 46242 | B12: =SUMIF(Dataset_Principal!$B$2:$B$51,A12,Dataset_Principal!$F$2:$F$51) -> 79998
A13: 46243 | B13: =SUMIF(Dataset_Principal!$B$2:$B$51,A13,Dataset_Principal!$F$2:$F$51) -> 0
A14: 46244 | B14: =SUMIF(Dataset_Principal!$B$2:$B$51,A14,Dataset_Principal!$F$2:$F$51) -> 59999
A15: 46245 | B15: =SUMIF(Dataset_Principal!$B$2:$B$51,A15,Dataset_Principal!$F$2:$F$51) -> 179996
A16: 46246 | B16: =SUMIF(Dataset_Principal!$B$2:$B$51,A16,Dataset_Principal!$F$2:$F$51) -> 249996
... A35: 46265 | B35: =SUMIF(Dataset_Principal!$B$2:$B$51,A35,Dataset_Principal!$F$2:$F$51) -> 59998
A36: 46266 | C36: =FORECAST(A36,$B$5:$B$35,$A$5:$A$35) -> 76224.065 | D36: =MAX(0,C36-1.96*STDEV($B$5:$B$35)) -> 0 | E36: =C36+1.96*STDEV($B$5:$B$35) -> 226012.28
A37: 46267 | C37: =FORECAST(A37,$B$5:$B$35,$A$5:$A$35) -> 74455.944 | D37: =MAX(0,C37-1.96*STDEV($B$5:$B$35)) -> 0 | E37: =C37+1.96*STDEV($B$5:$B$35) -> 224244.16
A38: 46268 | C38: =FORECAST(A38,$B$5:$B$35,$A$5:$A$35) -> 72687.823 | D38: =MAX(0,C38-1.96*STDEV($B$5:$B$35)) -> 0 | E38: =C38+1.96*STDEV($B$5:$B$35) -> 222476.04

Sheet Buscador
A1: Buscador de videojuegos
A3: Ingresá el ID del juego: | B3: J-008
A5: Videojuego: | B5: =_xlfn.XLOOKUP(B3,Cat_Juegos!$A$2:$A$11,Cat_Juegos!$B$2:$B$11,"No encontrado") -> Super Mario Bros. Wonder
A6: Género: | B6: =_xlfn.XLOOKUP(B3,Cat_Juegos!$A$2:$A$11,Cat_Juegos!$C$2:$C$11,"No encontrado") -> Plataformas
A7: Plataforma: | B7: =_xlfn.XLOOKUP(B3,Cat_Juegos!$A$2:$A$11,Cat_Juegos!$D$2:$D$11,"No encontrado") -> Nintendo Switch
A8: Precio: | B8: =_xlfn.XLOOKUP(B3,Cat_Juegos!$A$2:$A$11,Cat_Juegos!$E$2:$E$11,"No encontrado") -> 59999

Sheet Justificacion
A1: Justificación
A3: Elegí clasificar las ventas en altas, medias y bajas porque permite identificar de forma rápida qué operaciones tienen mayor importancia para una tienda de videojuegos.
A4: La previsión se hizo para 3 días futuros porque el dataset es pequeño y tiene información diaria; me pareció más realista hacer una proyección corta que intentar estimar muchos meses.
A5: El buscador permite ingresar el ID de un juego y obtener automáticamente su nombre, género, plataforma y precio.
A6: Las fórmulas están protegidas para evitar cambios accidentales y la celda de búsqueda queda habilitada para el usuario.

Sheet Cat_Juegos
A1: ID_Juego | B1: Videojuego | C1: Genero | D1: Plataforma | E1: Precio_Unitario
A2: J-001 | B2: Minecraft | C2: Sandbox | D2: PC | E2: 29999
A3: J-002 | B3: EA Sports FC 26 | C3: Deportes | D3: PS5 | E3: 69999
A4: J-003 | B4: Mario Kart 8 Deluxe | C4: Carreras | D4: Nintendo Switch | E4: 59999
A5: J-004 | B5: Fortnite | C5: Battle Royale | D5: PC | E5: 0
A6: J-005 | B6: The Sims 4 | C6: Simulación | D6: PC | E6: 0
A7: J-006 | B7: Grand Theft Auto V | C7: Acción | D7: PS5 | E7: 39999
A8: J-007 | B8: Hogwarts Legacy | C8: Aventura | D8: PS5 | E8: 49999
A9: J-008 | B9: Super Mario Bros. Wonder | C9: Plataformas | D9: Nintendo Switch | E9: 59999
A10: J-009 | B10: Forza Horizon 5 | C10: Carreras | D10: Xbox | E10: 44999
A11: J-010 | B11: Stardew Valley | C11: Simulación | D11: PC | E11: 14999

Sheet Cat_Clientes
A1: ID_Cliente | B1: Nombre | C1: Ciudad
A2: C-001 | B2: Martín | C2: La Plata
A3: C-002 | B3: Sofía | C3: Córdoba
A4: C-003 | B4: Lucas | C4: Rosario
A5: C-004 | B5: Camila | C5: Mendoza
A6: C-005 | B6: Tomás | C6: La Plata
A7: C-006 | B7: Valentina | C7: Mar del Plata
A8: C-007 | B8: Nicolás | C8: Buenos Aires
A9: C-008 | B9: Julieta | C9: Santa Fe
A10: C-009 | B10: Mateo | C10: Neuquén
A11: C-010 | B11: Agustina | C11: Tucumán

Sheet Reporte_Insights
A1: REPORTE DE INSIGHTS – VENTAS DE VIDEOJUEGOS
A2: Análisis de las ventas registradas durante agosto de 2026
A4: KPI | B4: Valor
A5: Facturación total | B5: =SUM(Dataset_Principal!F2:F51) -> 3239934
A6: Cantidad de operaciones | B6: =COUNTA(Dataset_Principal!A2:A51) -> 50
A7: Ticket promedio | B7: =AVERAGE(Dataset_Principal!F2:F51) -> 64798.68
A8: Ventas altas | B8: =COUNTIF(Calculos!E2:E51,"Venta Alta") -> 9
A9: Facturación de juegos de PS5 | B9: =SUMIF(Dataset_Principal!C2:C51,"J-002",Dataset_Principal!F2:F51)+SUMIF(Dataset_Principal!C2:C51,"J-006",Dataset_Principal!F2:F51)+SUMIF(Dataset_Principal!C2:C51,"J-007",Dataset_Principal!F2:F51) -> 1649968
A10: REPORTE EJECUTIVO
A11: 1. EVIDENCIA | B11: En las 50 ventas analizadas se facturaron $3.239.934, con un promedio de $64.799 por operación. Los juegos de PS5 sumaron $1.649.968, cerca del 51% del total. También se registraron 9 ventas clasificadas como altas.
A14: 2. SIGNIFICADO | B14: Lo que más se destaca es que una parte importante de la facturación está concentrada en los juegos de PS5. Esto puede hacer que el resultado general dependa bastante de algunos títulos de mayor precio, mientras que otros juegos aportan menos dinero al total.
A17: 3. IMPACTO | B17: En la proyección de los tres días siguientes, la venta diaria estimada baja de $76.224 a $72.688, aproximadamente un 4,6%. Si esta tendencia se mantiene, la facturación diaria podría disminuir y el negocio seguiría dependiendo mucho de los productos de mayor valor.
A20: 4. ACCIÓN | B20: Una posible acción sería hacer promociones o combos con juegos pagos de otras plataformas para repartir mejor las ventas. Como meta inicial, se podría buscar un aumento del 10% en la facturación diaria promedio y revisar los resultados una vez por semana para ver si la estrategia funciona.
A22: Nota: la explicación del comportamiento es una interpretación posible a partir de los datos disponibles; no se cuenta con información de stock, promociones o costos para confirmar una causa.
A24: ID_Juego | B24: Videojuego | C24: Facturación | E24: Segmento | F24: Operaciones
A25: J-001 | B25: Minecraft | C25: =SUMIF(Dataset_Principal!$C$2:$C$51,A25,Dataset_Principal!$F$2:$F$51) -> 239992 | E25: Venta Alta | F25: =COUNTIF(Calculos!$E$2:$E$51,E25) -> 9
A26: J-002 | B26: EA Sports FC 26 | C26: =SUMIF(Dataset_Principal!$C$2:$C$51,A26,Dataset_Principal!$F$2:$F$51) -> 629991 | E26: Venta Media | F26: =COUNTIF(Calculos!$E$2:$E$51,E26) -> 17
A27: J-003 | B27: Mario Kart 8 Deluxe | C27: =SUMIF(Dataset_Principal!$C$2:$C$51,A27,Dataset_Principal!$F$2:$F$51) -> 479992 | E27: Venta Baja | F27: =COUNTIF(Calculos!$E$2:$E$51,E27) -> 24
A28: J-004 | B28: Fortnite | C28: =SUMIF(Dataset_Principal!$C$2:$C$51,A28,Dataset_Principal!$F$2:$F$51) -> 0
A29: J-005 | B29: The Sims 4 | C29: =SUMIF(Dataset_Principal!$C$2:$C$51,A29,Dataset_Principal!$F$2:$F$51) -> 0
A30: J-006 | B30: Grand Theft Auto V | C30: =SUMIF(Dataset_Principal!$C$2:$C$51,A30,Dataset_Principal!$F$2:$F$51) -> 519987
A31: J-007 | B31: Hogwarts Legacy | C31: =SUMIF(Dataset_Principal!$C$2:$C$51,A31,Dataset_Principal!$F$2:$F$51) -> 499990
A32: J-008 | B32: Super Mario Bros. Wonder | C32: =SUMIF(Dataset_Principal!$C$2:$C$51,A32,Dataset_Principal!$F$2:$F$51) -> 479992
A33: J-009 | B33: Forza Horizon 5 | C33: =SUMIF(Dataset_Principal!$C$2:$C$51,A33,Dataset_Principal!$F$2:$F$51) -> 359992
A34: J-010 | B34: Stardew Valley | C34: =SUMIF(Dataset_Principal!$C$2:$C$51,A34,Dataset_Principal!$F$2:$F$51) -> 29998

Sheet Matriz_Precios
A1: MATRIZ DE PRECIOS POR PLATAFORMA Y VIDEOJUEGO
A2: Plataforma | B2: Minecraft | C2: EA Sports FC 26 | D2: GTA V | E2: Hogwarts Legacy | F2: Stardew Valley
A3: PC | B3: 29999 | F3: 14999
A4: PS5 | C4: 69999 | D4: 39999 | E4: 49999
A5: Nintendo Switch
A6: Xbox
A8: Objetivo | B8: Organizar precios usando dos criterios: plataforma y videojuego.
A9: Relación con el proyecto | B9: Los precios y plataformas provienen del catálogo de videojuegos usado en las entregas anteriores.
A10: Lectura | B10: Una celda vacía significa que esa combinación no forma parte del catálogo actual.

Sheet Busqueda_2D
A1: BÚSQUEDA BIDIMENSIONAL DE PRECIOS
A3: Plataforma | B3: PS5
A4: Videojuego | B4: Hogwarts Legacy
A5: Precio encontrado | B5: =IFERROR(INDEX(Matriz_Precios!$B$3:$F$6,MATCH(B3,Matriz_Precios!$A$3:$A$6,0),MATCH(B4,Matriz_Precios!$B$2:$F$2,0)),"No disponible") -> 49999
A6: Interpretación | B6: La fórmula cruza la plataforma elegida con el videojuego y devuelve el precio correspondiente.
A8: Fórmula aplicada | B8: ÍNDICE + COINCIDIR + COINCIDIR
A9: Por qué es 2D | B9: Un COINCIDIR localiza la fila (plataforma) y el otro la columna (videojuego).

Sheet Vencimientos
A1: VENCIMIENTOS DE OPERACIONES EN DÍAS HÁBILES
A3: ID Venta | B3: Fecha de venta | C3: Plazo (días hábiles) | D3: Vencimiento proyectado | F3: Feriados personalizados
A4: V-001 | B4: 46235 | C4: 5 | D4: =WORKDAY(B4,C4,$F$4:$F$8) -> 46241 | F4: 46251
A5: V-004 | B5: 46238 | C5: 5 | D5: =WORKDAY(B5,C5,$F$4:$F$8) -> 46245 | F5: 46307
A6: V-002 | B6: 46236 | C6: 7 | D6: =WORKDAY(B6,C6,$F$4:$F$8) -> 46245 | F6: 46349
A7: V-005 | B7: 46239 | C7: 7 | D7: =WORKDAY(B7,C7,$F$4:$F$8) -> 46248 | F7: 46364
A8: V-003 | B8: 46237 | C8: 10 | D8: =WORKDAY(B8,C8,$F$4:$F$8) -> 46252 | F8: 46381
A9: V-006 | B9: 46240 | C9: 10 | D9: =WORKDAY(B9,C9,$F$4:$F$8) -> 46255
A11: Cómo funciona | B11: DIA.LAB calcula el vencimiento contando solamente días hábiles y excluyendo los feriados cargados en F4:F8.
A12: Relación con la base | B12: Se usaron IDs y fechas de ventas del mismo proyecto de videojuegos.
A13: Uso | B13: Si se modifica la fecha o el plazo, el vencimiento se actualiza automáticamente.

Sheet Auditoria
A1: AUDITORÍA DE UNA TOTALIZACIÓN DE VENTAS
A3: Venta | B3: Cantidad | C3: Total venta | D3: Observación
A4: V-001 | B4: 2 | C4: 119998 | D4: Incluida
A5: V-002 | B5: 1 | C5: 44999 | D5: Incluida
A6: V-003 | B6: 1 | C6: 49999 | D6: Incluida
A7: V-004 | B7: 2 | C7: 119998 | D7: Debe estar incluida
A9: Control | B9: Resultado | C9: Qué ocurre | D9: Corrección
A10: Total con referencia incompleta | B10: =SUM(C4:C6) -> 214996 | C10: La fórmula suma C4:C6 y deja afuera C7. | D10: Ampliar el rango hasta C7.
A11: Total corregido | B11: =SUM(C4:C7) -> 334994 | C11: Incluye las cuatro ventas del ejemplo. | D11: SUMA C4:C7.
A12: Diferencia detectada | B12: =B11-B10 -> 119998 | C12: Muestra cuánto dinero se estaba omitiendo.
A14: EVIDENCIA DE RASTREAR PRECEDENTES
A50: Conclusión: “Al utilizar Rastrear precedentes se observó que la fórmula del total incluía las celdas C4:C6 y dejaba afuera C7. Al corregir el rango, el total pasó de $214.996 a $334.994.”

Sheet Calculo_LET
A1: CÁLCULO DE IMPUESTO Y DESCUENTO CON LET
A3: Dato | B3: Valor
A4: Venta tomada como ejemplo | B4: 119998
A5: Descuento aplicado | B5: 0.05
A6: Tasa de impuesto | B6: 0.21
A7: Costo de envío | B7: 4500
A8: Referencia | B8: Ejemplo basado en una operación del Dataset_Principal.
A10: Versión | B10: Resultado
A11: Fórmula original | B11: =(B4*(1-B5))+(B4*(1-B5)*B6)+B7 -> 142437.7
A12: Fórmula refactorizada con LET | B12: 142437.7
A13: Diferencia entre resultados | B13: =B12-B11 -> 0
A15: Qué aporta LET
A16: 1. | B16: Permite asignar nombres a las partes del cálculo.
A17: 2. | B17: Evita repetir operaciones dentro de una fórmula larga.
A18: 3. | B18: Facilita revisar de dónde sale cada resultado.
A19: 4. | B19: La fórmula original y la versión con LET deben producir el mismo total.

Sheet Base_Motor
A1: ID_Venta | B1: Fecha | C1: ID_Juego | D1: Videojuego | E1: Genero | F1: Plataforma | G1: ID_Cliente | H1: Cliente | I1: Ciudad | J1: Cantidad | K1: Total_Venta
A2: =Dataset_Principal!A2 -> V-001 | B2: =Dataset_Principal!B2 -> 46235 | C2: =Dataset_Principal!C2 -> J-008 | D2: =_xlfn.XLOOKUP(C2,Cat_Juegos!$A$2:$A$11,Cat_Juegos!$B$2:$B$11,"No encontrado") -> Super Mario Bros. Wonder | E2: =_xlfn.XLOOKUP(C2,Cat_Juegos!$A$2:$A$11,Cat_Juegos!$C$2:$C$11,"No encontrado") -> Plataformas | F2: =_xlfn.XLOOKUP(C2,Cat_Juegos!$A$2:$A$11,Cat_Juegos!$D$2:$D$11,"No encontrado") -> Nintendo Switch | G2: =Dataset_Principal!D2 -> C-005 | H2: =_xlfn.XLOOKUP(G2,Cat_Clientes!$A$2:$A$11,Cat_Clientes!$B$2:$B$11,"No encontrado") -> Tomás | I2: =_xlfn.XLOOKUP(G2,Cat_Clientes!$A$2:$A$11,Cat_Clientes!$C$2:$C$11,"No encontrado") -> La Plata | J2: =Dataset_Principal!E2 -> 2 | K2: =Dataset_Principal!F2 -> 119998
A3: =Dataset_Principal!A3 -> V-002 | B3: =Dataset_Principal!B3 -> 46236 | C3: =Dataset_Principal!C3 -> J-009 | D3: =_xlfn.XLOOKUP(C3,Cat_Juegos!$A$2:$A$11,Cat_Juegos!$B$2:$B$11,"No encontrado") -> Forza Horizon 5 | E3: =_xlfn.XLOOKUP(C3,Cat_Juegos!$A$2:$A$11,Cat_Juegos!$C$2:$C$11,"No encontrado") -> Carreras | F3: =_xlfn.XLOOKUP(C3,Cat_Juegos!$A$2:$A$11,Cat_Juegos!$D$2:$D$11,"No encontrado") -> Xbox | G3: =Dataset_Principal!D3 -> C-006 | H3: =_xlfn.XLOOKUP(G3,Cat_Clientes!$A$2:$A$11,Cat_Clientes!$B$2:$B$11,"No encontrado") -> Valentina | I3: =_xlfn.XLOOKUP(G3,Cat_Clientes!$A$2:$A$11,Cat_Clientes!$C$2:$C$11,"No encontrado") -> Mar del Plata | J3: =Dataset_Principal!E3 -> 1 | K3: =Dataset_Principal!F3 -> 44999
A4: =Dataset_Principal!A4 -> V-003 | B4: =Dataset_Principal!B4 -> 46237 | C4: =Dataset_Principal!C4 -> J-007 | D4: =_xlfn.XLOOKUP(C4,Cat_Juegos!$A$2:$A$11,Cat_Juegos!$B$2:$B$11,"No encontrado") -> Hogwarts Legacy | E4: =_xlfn.XLOOKUP(C4,Cat_Juegos!$A$2:$A$11,Cat_Juegos!$C$2:$C$11,"No encontrado") -> Aventura | F4: =_xlfn.XLOOKUP(C4,Cat_Juegos!$A$2:$A$11,Cat_Juegos!$D$2:$D$11,"No encontrado") -> PS5 | G4: =Dataset_Principal!D4 -> C-001 | H4: =_xlfn.XLOOKUP(G4,Cat_Clientes!$A$2:$A$11,Cat_Clientes!$B$2:$B$11,"No encontrado") -> Martín | I4: =_xlfn.XLOOKUP(G4,Cat_Clientes!$A$2:$A$11,Cat_Clientes!$C$2:$C$11,"No encontrado") -> La Plata | J4: =Dataset_Principal!E4 -> 1 | K4: =Dataset_Principal!F4 -> 49999
A5: =Dataset_Principal!A5 -> V-004 | B5: =Dataset_Principal!B5 -> 46238 | C5: =Dataset_Principal!C5 -> J-008 | D5: =_xlfn.XLOOKUP(C5,Cat_Juegos!$A$2:$A$11,Cat_Juegos!$B$2:$B$11,"No encontrado") -> Super Mario Bros. Wonder | E5: =_xlfn.XLOOKUP(C5,Cat_Juegos!$A$2:$A$11,Cat_Juegos!$C$2:$C$11,"No encontrado") -> Plataformas | F5: =_xlfn.XLOOKUP(C5,Cat_Juegos!$A$2:$A$11,Cat_Juegos!$D$2:$D$11,"No encontrado") -> Nintendo Switch | G5: =Dataset_Principal!D5 -> C-005 | H5: =_xlfn.XLOOKUP(G5,Cat_Clientes!$A$2:$A$11,Cat_Clientes!$B$2:$B$11,"No encontrado") -> Tomás | I5: =_xlfn.XLOOKUP(G5,Cat_Clientes!$A$2:$A$11,Cat_Clientes!$C$2:$C$11,"No encontrado") -> La Plata | J5: =Dataset_Principal!E5 -> 2 | K5: =Dataset_Principal!F5 -> 119998
A6: =Dataset_Principal!A6 -> V-005 | B6: =Dataset_Principal!B6 -> 46239 | C6: =Dataset_Principal!C6 -> J-008 | D6: =_xlfn.XLOOKUP(C6,Cat_Juegos!$A$2:$A$11,Cat_Juegos!$B$2:$B$11,"No encontrado") -> Super Mario Bros. Wonder | E6: =_xlfn.XLOOKUP(C6,Cat_Juegos!$A$2:$A$11,Cat_Juegos!$C$2:$C$11,"No encontrado") -> Plataformas | F6: =_xlfn.XLOOKUP(C6,Cat_Juegos!$A$2:$A$11,Cat_Juegos!$D$2:$D$11,"No encontrado") -> Nintendo Switch | G6: =Dataset_Principal!D6 -> C-010 | H6: =_xlfn.XLOOKUP(G6,Cat_Clientes!$A$2:$A$11,Cat_Clientes!$B$2:$B$11,"No encontrado") -> Agustina | I6: =_xlfn.XLOOKUP(G6,Cat_Clientes!$A$2:$A$11,Cat_Clientes!$C$2:$C$11,"No encontrado") -> Tucumán | J6: =Dataset_Principal!E6 -> 1 | K6: =Dataset_Principal!F6 -> 59999
A7: =Dataset_Principal!A7 -> V-006 | B7: =Dataset_Principal!B7 -> 46240 | C7: =Dataset_Principal!C7 -> J-009 | D7: =_xlfn.XLOOKUP(C7,Cat_Juegos!$A$2:$A$11,Cat_Juegos!$B$2:$B$11,"No encontrado") -> Forza Horizon 5 | E7: =_xlfn.XLOOKUP(C7,Cat_Juegos!$A$2:$A$11,Cat_Juegos!$C$2:$C$11,"No encontrado") -> Carreras | F7: =_xlfn.XLOOKUP(C7,Cat_Juegos!$A$2:$A$11,Cat_Juegos!$D$2:$D$11,"No encontrado") -> Xbox | G7: =Dataset_Principal!D7 -> C-001 | H7: =_xlfn.XLOOKUP(G7,Cat_Clientes!$A$2:$A$11,Cat_Clientes!$B$2:$B$11,"No encontrado") -> Martín | I7: =_xlfn.XLOOKUP(G7,Cat_Clientes!$A$2:$A$11,Cat_Clientes!$C$2:$C$11,"No encontrado") -> La Plata | J7: =Dataset_Principal!E7 -> 2 | K7: =Dataset_Principal!F7 -> 89998
A8: =Dataset_Principal!A8 -> V-007 | B8: =Dataset_Principal!B8 -> 46241 | C8: =Dataset_Principal!C8 -> J-010 | D8: =_xlfn.XLOOKUP(C8,Cat_Juegos!$A$2:$A$11,Cat_Juegos!$B$2:$B$11,"No encontrado") -> Stardew Valley | E8: =_xlfn.XLOOKUP(C8,Cat_Juegos!$A$2:$A$11,Cat_Juegos!$C$2:$C$11,"No encontrado") -> Simulación | F8: =_xlfn.XLOOKUP(C8,Cat_Juegos!$A$2:$A$11,Cat_Juegos!$D$2:$D$11,"No encontrado") -> PC | G8: =Dataset_Principal!D8 -> C-003 | H8: =_xlfn.XLOOKUP(G8,Cat_Clientes!$A$2:$A$11,Cat_Clientes!$B$2:$B$11,"No encontrado") -> Lucas | I8: =_xlfn.XLOOKUP(G8,Cat_Clientes!$A$2:$A$11,Cat_Clientes!$C$2:$C$11,"No encontrado") -> Rosario | J8: =Dataset_Principal!E8 -> 1 | K8: =Dataset_Principal!F8 -> 14999
A9: =Dataset_Principal!A9 -> V-008 | B9: =Dataset_Principal!B9 -> 46242 | C9: =Dataset_Principal!C9 -> J-006 | D9: =_xlfn.XLOOKUP(C9,Cat_Juegos!$A$2:$A$11,Cat_Juegos!$B$2:$B$11,"No encontrado") -> Grand Theft Auto V | E9: =_xlfn.XLOOKUP(C9,Cat_Juegos!$A$2:$A$11,Cat_Juegos!$C$2:$C$11,"No encontrado") -> Acción | F9: =_xlfn.XLOOKUP(C9,Cat_Juegos!$A$2:$A$11,Cat_Juegos!$D$2:$D$11,"No encontrado") -> PS5 | G9: =Dataset_Principal!D9 -> C-003 | H9: =_xlfn.XLOOKUP(G9,Cat_Clientes!$A$2:$A$11,Cat_Clientes!$B$2:$B$11,"No encontrado") -> Lucas | I9: =_xlfn.XLOOKUP(G9,Cat_Clientes!$A$2:$A$11,Cat_Clientes!$C$2:$C$11,"No encontrado") -> Rosario | J9: =Dataset_Principal!E9 -> 1 | K9: =Dataset_Principal!F9 -> 39999
A10: =Dataset_Principal!A10 -> V-009 | B10: =Dataset_Principal!B10 -> 46243 | C10: =Dataset_Principal!C10 -> J-004 | D10: =_xlfn.XLOOKUP(C10,Cat_Juegos!$A$2:$A$11,Cat_Juegos!$B$2:$B$11,"No encontrado") -> Fortnite | E10: =_xlfn.XLOOKUP(C10,Cat_Juegos!$A$2:$A$11,Cat_Juegos!$C$2:$C$11,"No encontrado") -> Battle Royale | F10: =_xlfn.XLOOKUP(C10,Cat_Juegos!$A$2:$A$11,Cat_Juegos!$D$2:$D$11,"No encontrado") -> PC | G10: =Dataset_Principal!D10 -> C-001 | H10: =_xlfn.XLOOKUP(G10,Cat_Clientes!$A$2:$A$11,Cat_Clientes!$B$2:$B$11,"No encontrado") -> Martín | I10: =_xlfn.XLOOKUP(G10,Cat_Clientes!$A$2:$A$11,Cat_Clientes!$C$2:$C$11,"No encontrado") -> La Plata | J10: =Dataset_Principal!E10 -> 2 | K10: =Dataset_Principal!F10 -> 0
A11: =Dataset_Principal!A11 -> V-010 | B11: =Dataset_Principal!B11 -> 46244 | C11: =Dataset_Principal!C11 -> J-004 | D11: =_xlfn.XLOOKUP(C11,Cat_Juegos!$A$2:$A$11,Cat_Juegos!$B$2:$B$11,"No encontrado") -> Fortnite | E11: =_xlfn.XLOOKUP(C11,Cat_Juegos!$A$2:$A$11,Cat_Juegos!$C$2:$C$11,"No encontrado") -> Battle Royale | F11: =_xlfn.XLOOKUP(C11,Cat_Juegos!$A$2:$A$11,Cat_Juegos!$D$2:$D$11,"No encontrado") -> PC | G11: =Dataset_Principal!D11 -> C-002 | H11: =_xlfn.XLOOKUP(G11,Cat_Clientes!$A$2:$A$11,Cat_Clientes!$B$2:$B$11,"No encontrado") -> Sofía | I11: =_xlfn.XLOOKUP(G11,Cat_Clientes!$A$2:$A$11,Cat_Clientes!$C$2:$C$11,"No encontrado") -> Córdoba | J11: =Dataset_Principal!E11 -> 2 | K11: =Dataset_Principal!F11 -> 0
A12: =Dataset_Principal!A12 -> V-011 | B12: =Dataset_Principal!B12 -> 46245 | C12: =Dataset_Principal!C12 -> J-006 | D12: =_xlfn.XLOOKUP(C12,Cat_Juegos!$A$2:$A$11,Cat_Juegos!$B$2:$B$11,"No encontrado") -> Grand Theft Auto V | E12: =_xlfn.XLOOKUP(C12,Cat_Juegos!$A$2:$A$11,Cat_Juegos!$C$2:$C$11,"No encontrado") -> Acción | F12: =_xlfn.XLOOKUP(C12,Cat_Juegos!$A$2:$A$11,Cat_Juegos!$D$2:$D$11,"No encontrado") -> PS5 | G12: =Dataset_Principal!D12 -> C-007 | H12: =_xlfn.XLOOKUP(G12,Cat_Clientes!$A$2:$A$11,Cat_Clientes!$B$2:$B$11,"No encontrado") -> Nicolás | I12: =_xlfn.XLOOKUP(G12,Cat_Clientes!$A$2:$A$11,Cat_Clientes!$C$2:$C$11,"No encontrado") -> Buenos Aires | J12: =Dataset_Principal!E12 -> 3 | K12: =Dataset_Principal!F12 -> 119997
A13: =Dataset_Principal!A13 -> V-012 | B13: =Dataset_Principal!B13 -> 46246 | C13: =Dataset_Principal!C13 -> J-002 | D13: =_xlfn.XLOOKUP(C13,Cat_Juegos!$A$2:$A$11,Cat_Juegos!$B$2:$B$11,"No encontrado") -> EA Sports FC 26 | E13: =_xlfn.XLOOKUP(C13,Cat_Juegos!$A$2:$A$11,Cat_Juegos!$C$2:$C$11,"No encontrado") -> Deportes | F13: =_xlfn.XLOOKUP(C13,Cat_Juegos!$A$2:$A$11,Cat_Juegos!$D$2:$D$11,"No encontrado") -> PS5 | G13: =Dataset_Principal!D13 -> C-001 | H13: =_xlfn.XLOOKUP(G13,Cat_Clientes!$A$2:$A$11,Cat_Clientes!$B$2:$B$11,"No encontrado") -> Martín | I13: =_xlfn.XLOOKUP(G13,Cat_Clientes!$A$2:$A$11,Cat_Clientes!$C$2:$C$11,"No encontrado") -> La Plata | J13: =Dataset_Principal!E13 -> 1 | K13: =Dataset_Principal!F13 -> 69999
... A51: =Dataset_Principal!A51 -> V-050 | B51: =Dataset_Principal!B51 -> 46253 | C51: =Dataset_Principal!C51 -> J-006 | D51: =_xlfn.XLOOKUP(C51,Cat_Juegos!$A$2:$A$11,Cat_Juegos!$B$2:$B$11,"No encontrado") -> Grand Theft Auto V | E51: =_xlfn.XLOOKUP(C51,Cat_Juegos!$A$2:$A$11,Cat_Juegos!$C$2:$C$11,"No encontrado") -> Acción | F51: =_xlfn.XLOOKUP(C51,Cat_Juegos!$A$2:$A$11,Cat_Juegos!$D$2:$D$11,"No encontrado") -> PS5 | G51: =Dataset_Principal!D51 -> C-005 | H51: =_xlfn.XLOOKUP(G51,Cat_Clientes!$A$2:$A$11,Cat_Clientes!$B$2:$B$11,"No encontrado") -> Tomás | I51: =_xlfn.XLOOKUP(G51,Cat_Clientes!$A$2:$A$11,Cat_Clientes!$C$2:$C$11,"No encontrado") -> La Plata | J51: =Dataset_Principal!E51 -> 2 | K51: =Dataset_Principal!F51 -> 79998

Sheet Detalle1
A1: Detalles para Suma de Total_Venta - Videojuego: Minecraft
A3: ID_Venta | B3: Fecha | C3: ID_Juego | D3: Videojuego | E3: Genero | F3: Plataforma | G3: ID_Cliente | H3: Cliente | I3: Ciudad | J3: Cantidad | K3: Total_Venta
A4: V-047 | B4: 46250 | C4: J-001 | D4: Minecraft | E4: Sandbox | F4: PC | G4: C-004 | H4: Camila | I4: Mendoza | J4: 2 | K4: 59998
A5: V-038 | B5: 46241 | C5: J-001 | D5: Minecraft | E5: Sandbox | F5: PC | G5: C-009 | H5: Mateo | I5: Neuquén | J5: 1 | K5: 29999
A6: V-031 | B6: 46265 | C6: J-001 | D6: Minecraft | E6: Sandbox | F6: PC | G6: C-004 | H6: Camila | I6: Mendoza | J6: 2 | K6: 59998
A7: V-029 | B7: 46263 | C7: J-001 | D7: Minecraft | E7: Sandbox | F7: PC | G7: C-007 | H7: Nicolás | I7: Buenos Aires | J7: 3 | K7: 89997

Sheet Motor_Analisis
A3: Facturación por Videojuego | B3: Suma de Total_Venta | D3: Facturación por Plataforma | E3: Suma de Total_Venta | G3: Facturación por Ciudad | H3: Suma de Total_Venta
A4: EA Sports FC 26 | B4: 629991 | D4: Nintendo Switch | E4: 959984 | G4: Buenos Aires | H4: 349992
A5: Fortnite | B5: 0 | D5: PC | E5: 269990 | G5: Córdoba | H5: 0
A6: Forza Horizon 5 | B6: 359992 | D6: PS5 | E6: 1649968 | G6: La Plata | H6: 1059980
A7: Grand Theft Auto V | B7: 519987 | D7: Xbox | E7: 359992 | G7: Mar del Plata | H7: 264995
A8: Hogwarts Legacy | B8: 499990 | D8: Total general | E8: 3239934 | G8: Mendoza | H8: 699986
A9: Mario Kart 8 Deluxe | B9: 479992 | G9: Neuquén | H9: 284994
A10: Minecraft | B10: 239992 | G10: Rosario | H10: 199995
A11: Stardew Valley | B11: 29998 | G11: Santa Fe | H11: 49999
A12: Super Mario Bros. Wonder | B12: 479992 | G12: Tucumán | H12: 329993
A13: The Sims 4 | B13: 0 | G13: Total general | H13: 3239934
A14: Total general | B14: 3239934

Sheet Data_Clientes
A1: ID_Cliente | B1: Nombre | C1: Empresa
A2: C-001 | B2: Martín | C2: GameTech SA
A3: C-002 | B3: Sofía | C3: Pixel Corp
A4: C-003 | B4: Lucas | C4: NextPlay SRL
A5: C-004 | B5: Camila | C5: Digital Games SA
A6: C-005 | B6: Tomás | C6: GameTech SA
A7: C-006 | B7: Valentina | C7: PlayZone SRL
A8: C-007 | B8: Nicolás | C8: Nova Gaming
A9: C-008 | B9: Julieta | C9: LevelUp SA
A10: C-009 | B10: Mateo | C10: VirtualPlay SRL
A11: C-010 | B11: Agustina | C11: GameStore SA

Sheet Historico_Simulaciones
A1: ID_Simulacion | B1: Fecha | C1: ID_Cliente | D1: Monto | E1: Tasa_Anual | F1: Plazo_Meses | G1: Cuota_Mensual | H1: Valor_Futuro
A2: S-001 | B2: 46266 | C2: C-001 | D2: 500000 | E2: 0.3 | F2: 12 | G2: 48743.563 | H2: 672444.41
A3: S-002 | B3: 46267 | C3: C-003 | D3: 350000 | E3: 0.24 | F3: 18 | G3: 23345.736 | H3: 499886.19
A4: S-003 | B4: 46268 | C4: C-005 | D4: 750000 | E4: 0.36 | F4: 24 | G4: 44285.562 | H4: 1524595.6
A5: S-004 | B5: 46289 | C5: C-001 | D5: 500000 | E5: 0.3 | F5: 12 | G5: 48743.563 | H5: 672444.41
A6: S-005 | B6: 46289 | C6: C-003 | D6: 600000 | E6: 0.24 | F6: 18 | G6: 40021.261 | H6: 856947.75

Sheet Dashboard
A1: SIMULADOR FINANCIERO
A3: ID Cliente | B3: C-003
A4: Monto | B4: 600000
A5: Tasa Anual | B5: 0.24
A6: Plazo (meses) | B6: 18
A8: Cuota Mensual | B8: =-PMT(B5/12,B6,B4) -> 40021.261
A9: Valor Futuro | B9: =FV(B5/12,B6,0,-B4) -> 856947.75

Sheet Reporte_Ejecutivo
B3: Etiquetas de columna
B4: Nintendo Switch | D4: PC | F4: PS5 | H4: Xbox | J4: Total Suma de Total_Venta | K4: Total Suma de Total_Venta2
A5: Etiquetas de fila | B5: Suma de Total_Venta | C5: Suma de Total_Venta2 | D5: Suma de Total_Venta | E5: Suma de Total_Venta2 | F5: Suma de Total_Venta | G5: Suma de Total_Venta2 | H5: Suma de Total_Venta | I5: Suma de Total_Venta2
A6: Acción | C6: 0 | E6: 0 | F6: 399990 | G6: 0.11428527 | I6: 0 | J6: 399990 | K6: 0.11428527
A7: Aventura | C7: 0 | E7: 0 | F7: 349993 | G7: 0.10000011 | I7: 0 | J7: 349993 | K7: 0.10000011
A8: Battle Royale | C8: 0 | D8: 0 | E8: 0 | G8: 0 | I8: 0 | J8: 0 | K8: 0
A9: Carreras | B9: 599990 | C9: 0.17142934 | E9: 0 | G9: 0 | H9: 314993 | I9: 0.089999903 | J9: 914983 | K9: 0.26142924
A10: Deportes | C10: 0 | E10: 0 | F10: 769989 | G10: 0.22000151 | I10: 0 | J10: 769989 | K10: 0.22000151
A11: Plataformas | B11: 659989 | C11: 0.18857227 | E11: 0 | G11: 0 | I11: 0 | J11: 659989 | K11: 0.18857227
A12: Sandbox | C12: 0 | D12: 269991 | E12: 0.077141917 | G12: 0 | I12: 0 | J12: 269991 | K12: 0.077141917
A13: Simulación | C13: 0 | D13: 134991 | E13: 0.038569673 | G13: 0 | I13: 0 | J13: 134991 | K13: 0.038569673
A14: Total general | B14: 1259979 | C14: 0.36000161 | D14: 404982 | E14: 0.11571159 | F14: 1519972 | G14: 0.4342869 | H14: 314993 | I14: 0.089999903 | J14: 3499926 | K14: 1

Sheet Datos_ETL

Sheet Evaluación_Financiera
A1: EVALUACIÓN FINANCIERA – PROYECTO DE EXPANSIÓN
A3: Inversión inicial | B3: 1000000
A4: Tasa anual préstamo | B4: 0.3
A5: Plazo préstamo (meses) | B5: 36
A6: Cuota mensual | B6: =-PMT(B4/12,B5,B3) -> 42451.577
A8: Costo de capital anual | B8: 0.15
A10: Año | B10: Flujo de caja
A11: 0 | B11: -1000000
A12: 1 | B12: 280000
A13: 2 | B13: 320000
A14: 3 | B14: 360000
A15: 4 | B15: 400000
A16: 5 | B16: 450000
A17: VAN | B17: =NPV(B8,B12:B16)+B11 -> 174580.91
A18: TIR | B18: =IRR(B11:B16) -> 0.21561375
A20: Conclusión | B20: El proyecto es viable: presenta un VAN positivo y una TIR superior al costo de capital.
